<?xml version="1.0"?>

<robot name="diff_robot" xmlns:xacro="http://www.ros.org/wiki/xacro">

    <xacro:property name="M_PI" value="3.1415926535897931" />
    <!--Material Definition-->  
    <material name="Black">
      <color rgba="0.0 0.0 0.0 1.0"/>
    </material>
    <material name="White">
      <color rgba="1.0 1.0 1.0 1.0"/>
    </material>  
  
    <xacro:macro name="cylinder_inertia" params="m r h">
        <inertia  ixx="${m*(3*r*r+h*h)/12}" ixy = "0" ixz = "0"
                iyy="${m*(3*r*r+h*h)/12}" iyz = "0"
                izz="${m*r*r/2}" /> 
    </xacro:macro>
    

    <xacro:macro name="passive_wheel_joint" params="name parent child *origin">
      <joint name="${name}" type="fixed" >
        <parent link="${parent}" />
        <child link="${child}" />
        <xacro:insert_block name="origin" />
      </joint>
    </xacro:macro>

    <xacro:macro name="passive_wheel_link" params="name *origin">
        <link name="${name}">
            <visual>
                <xacro:insert_block name="origin" />
                <geometry>
                    <sphere radius="${passive_wheel_radius}" />
                </geometry>
                <material name="Black" />
            </visual>  
            <collision>
                <geometry>
                    <sphere radius="${passive_wheel_radius}" />
                </geometry>
                <origin xyz="0 0.02 0" rpy="${M_PI/2} 0 0" />
            </collision>      
            <inertial>
                <mass value="${passive_wheel_mass}" />
                    <origin xyz="0 0 0" />
                    <inertia  ixx="0.001" ixy="0.0" ixz="0.0"
                            iyy="0.001" iyz="0.0" 
                                izz="0.001" />
            </inertial>
        </link>
    </xacro:macro>
	
  <xacro:macro name="wheel" params="side parent translateX translateY"> 
    <link name="${side}_wheel">
      <visual>
        <origin xyz="0 0 0" rpy="${M_PI/2} 0  0 " /> 
        <geometry>
          <cylinder length="${wheel_height}" radius="${wheel_radius}" />
        </geometry>
              <material name="Black" />
      </visual>
      <collision>
        <origin xyz="0 0 0" rpy="${M_PI/2} 0 0 " />
        <geometry>
          <cylinder length="${wheel_height}" radius="${wheel_radius}" />
        </geometry>
      </collision>
      <inertial>
        <mass value="${wheel_mass}" />
        <origin xyz="0 0 0" />
				<inertia ixx="0.001" ixy="0.0" ixz="0.0"
               iyy="0.001" iyz="0.0" 
               izz="0.001" />
      </inertial>
    </link>


    <joint name="${side}_wheel_joint" type="continuous">
      <parent link="${parent}"/>
      <child link="${side}_wheel"/>
      
        <origin xyz="0 ${translateY} 0" rpy="0 0 0" /> 
      <axis xyz="0 1 0" rpy="0 0 0" />
      <limit effort="100" velocity="100"/>
      <joint_properties damping="0.0" friction="0.0"/>
    </joint>

  </xacro:macro>
</robot>